[2024-11-29T20:47:59.361+0000] {local_task_job_runner.py:120} INFO - ::group::Pre task execution logs
[2024-11-29T20:47:59.417+0000] {taskinstance.py:2076} INFO - Dependencies all met for dep_context=non-requeueable deps ti=<TaskInstance: Electricity_predict.predict scheduled__2024-11-28T20:30:00+00:00 [queued]>
[2024-11-29T20:47:59.424+0000] {taskinstance.py:2076} INFO - Dependencies all met for dep_context=requeueable deps ti=<TaskInstance: Electricity_predict.predict scheduled__2024-11-28T20:30:00+00:00 [queued]>
[2024-11-29T20:47:59.425+0000] {taskinstance.py:2306} INFO - Starting attempt 1 of 1
[2024-11-29T20:47:59.440+0000] {taskinstance.py:2330} INFO - Executing <Task(_PythonDecoratedOperator): predict> on 2024-11-28 20:30:00+00:00
[2024-11-29T20:47:59.455+0000] {standard_task_runner.py:90} INFO - Running: ['***', 'tasks', 'run', 'Electricity_predict', 'predict', 'scheduled__2024-11-28T20:30:00+00:00', '--job-id', '285', '--raw', '--subdir', 'DAGS_FOLDER/energy_usage_prediction.py', '--cfg-path', '/tmp/tmpbi0i6sjv']
[2024-11-29T20:47:59.456+0000] {logging_mixin.py:188} WARNING - /home/***/.local/lib/python3.12/site-packages/***/task/task_runner/standard_task_runner.py:61 DeprecationWarning: This process (pid=16583) is multi-threaded, use of fork() may lead to deadlocks in the child.
[2024-11-29T20:47:59.457+0000] {standard_task_runner.py:91} INFO - Job 285: Subtask predict
[2024-11-29T20:47:59.457+0000] {standard_task_runner.py:63} INFO - Started process 16596 to run task
[2024-11-29T20:47:59.579+0000] {task_command.py:426} INFO - Running <TaskInstance: Electricity_predict.predict scheduled__2024-11-28T20:30:00+00:00 [running]> on host fd43cd87157f
[2024-11-29T20:47:59.700+0000] {taskinstance.py:2648} INFO - Exporting env vars: AIRFLOW_CTX_DAG_OWNER='***' AIRFLOW_CTX_DAG_ID='Electricity_predict' AIRFLOW_CTX_TASK_ID='predict' AIRFLOW_CTX_EXECUTION_DATE='2024-11-28T20:30:00+00:00' AIRFLOW_CTX_TRY_NUMBER='1' AIRFLOW_CTX_DAG_RUN_ID='scheduled__2024-11-28T20:30:00+00:00'
[2024-11-29T20:47:59.714+0000] {taskinstance.py:430} INFO - ::endgroup::
[2024-11-29T20:48:00.239+0000] {logging_mixin.py:188} INFO - 002003 (02000): 01b8b3df-0004-386a-0002-595300039492: Uncaught exception of type 'STATEMENT_ERROR' on line 3 at position 4 : SQL compilation error:
Table 'DEV.ANALYTICS.WEATHER_FORECAST_PREDICT_INPUT' does not exist or not authorized.
[2024-11-29T20:48:00.240+0000] {taskinstance.py:441} INFO - ::group::Post task execution logs
[2024-11-29T20:48:00.246+0000] {taskinstance.py:2905} ERROR - Task failed with exception
Traceback (most recent call last):
  File "/home/airflow/.local/lib/python3.12/site-packages/airflow/models/taskinstance.py", line 465, in _execute_task
    result = _execute_callable(context=context, **execute_callable_kwargs)
             ^^^^^^^^^^^^^^^^^^^^^^^^^^^^^^^^^^^^^^^^^^^^^^^^^^^^^^^^^^^^^
  File "/home/airflow/.local/lib/python3.12/site-packages/airflow/models/taskinstance.py", line 432, in _execute_callable
    return execute_callable(context=context, **execute_callable_kwargs)
           ^^^^^^^^^^^^^^^^^^^^^^^^^^^^^^^^^^^^^^^^^^^^^^^^^^^^^^^^^^^^
  File "/home/airflow/.local/lib/python3.12/site-packages/airflow/models/baseoperator.py", line 400, in wrapper
    return func(self, *args, **kwargs)
           ^^^^^^^^^^^^^^^^^^^^^^^^^^^
  File "/home/airflow/.local/lib/python3.12/site-packages/airflow/decorators/base.py", line 265, in execute
    return_value = super().execute(context)
                   ^^^^^^^^^^^^^^^^^^^^^^^^
  File "/home/airflow/.local/lib/python3.12/site-packages/airflow/models/baseoperator.py", line 400, in wrapper
    return func(self, *args, **kwargs)
           ^^^^^^^^^^^^^^^^^^^^^^^^^^^
  File "/home/airflow/.local/lib/python3.12/site-packages/airflow/operators/python.py", line 235, in execute
    return_value = self.execute_callable()
                   ^^^^^^^^^^^^^^^^^^^^^^^
  File "/home/airflow/.local/lib/python3.12/site-packages/airflow/operators/python.py", line 252, in execute_callable
    return self.python_callable(*self.op_args, **self.op_kwargs)
           ^^^^^^^^^^^^^^^^^^^^^^^^^^^^^^^^^^^^^^^^^^^^^^^^^^^^^
  File "/opt/airflow/dags/energy_usage_prediction.py", line 115, in predict
    cur.execute(make_prediction_sql)
  File "/home/airflow/.local/lib/python3.12/site-packages/snowflake/connector/cursor.py", line 1080, in execute
    Error.errorhandler_wrapper(self.connection, self, error_class, errvalue)
  File "/home/airflow/.local/lib/python3.12/site-packages/snowflake/connector/errors.py", line 290, in errorhandler_wrapper
    handed_over = Error.hand_to_other_handler(
                  ^^^^^^^^^^^^^^^^^^^^^^^^^^^^
  File "/home/airflow/.local/lib/python3.12/site-packages/snowflake/connector/errors.py", line 345, in hand_to_other_handler
    cursor.errorhandler(connection, cursor, error_class, error_value)
  File "/home/airflow/.local/lib/python3.12/site-packages/snowflake/connector/errors.py", line 221, in default_errorhandler
    raise error_class(
snowflake.connector.errors.ProgrammingError: 002003 (02000): 01b8b3df-0004-386a-0002-595300039492: Uncaught exception of type 'STATEMENT_ERROR' on line 3 at position 4 : SQL compilation error:
Table 'DEV.ANALYTICS.WEATHER_FORECAST_PREDICT_INPUT' does not exist or not authorized.
[2024-11-29T20:48:00.378+0000] {taskinstance.py:1206} INFO - Marking task as FAILED. dag_id=Electricity_predict, task_id=predict, run_id=scheduled__2024-11-28T20:30:00+00:00, execution_date=20241128T203000, start_date=20241129T204759, end_date=20241129T204800
[2024-11-29T20:48:00.436+0000] {standard_task_runner.py:110} ERROR - Failed to execute job 285 for task predict (002003 (02000): 01b8b3df-0004-386a-0002-595300039492: Uncaught exception of type 'STATEMENT_ERROR' on line 3 at position 4 : SQL compilation error:
Table 'DEV.ANALYTICS.WEATHER_FORECAST_PREDICT_INPUT' does not exist or not authorized.; 16596)
[2024-11-29T20:48:00.485+0000] {local_task_job_runner.py:240} INFO - Task exited with return code 1
[2024-11-29T20:48:00.502+0000] {taskinstance.py:3498} INFO - 0 downstream tasks scheduled from follow-on schedule check
[2024-11-29T20:48:00.506+0000] {local_task_job_runner.py:222} INFO - ::endgroup::
