[2024-11-30T06:26:06.220+0000] {local_task_job_runner.py:120} INFO - ::group::Pre task execution logs
[2024-11-30T06:26:06.247+0000] {taskinstance.py:2076} INFO - Dependencies all met for dep_context=non-requeueable deps ti=<TaskInstance: complete-dag.dbt_run manual__2024-11-30T06:25:39.483660+00:00 [queued]>
[2024-11-30T06:26:06.255+0000] {taskinstance.py:2076} INFO - Dependencies all met for dep_context=requeueable deps ti=<TaskInstance: complete-dag.dbt_run manual__2024-11-30T06:25:39.483660+00:00 [queued]>
[2024-11-30T06:26:06.255+0000] {taskinstance.py:2306} INFO - Starting attempt 1 of 1
[2024-11-30T06:26:06.268+0000] {taskinstance.py:2330} INFO - Executing <Task(BashOperator): dbt_run> on 2024-11-30 06:25:39.483660+00:00
[2024-11-30T06:26:06.279+0000] {standard_task_runner.py:90} INFO - Running: ['***', 'tasks', 'run', 'complete-dag', 'dbt_run', 'manual__2024-11-30T06:25:39.483660+00:00', '--job-id', '352', '--raw', '--subdir', 'DAGS_FOLDER/complete_dag.py', '--cfg-path', '/tmp/tmpn5kbhj3_']
[2024-11-30T06:26:06.280+0000] {logging_mixin.py:188} WARNING - /home/***/.local/lib/python3.12/site-packages/***/task/task_runner/standard_task_runner.py:61 DeprecationWarning: This process (pid=9287) is multi-threaded, use of fork() may lead to deadlocks in the child.
[2024-11-30T06:26:06.282+0000] {standard_task_runner.py:91} INFO - Job 352: Subtask dbt_run
[2024-11-30T06:26:06.282+0000] {standard_task_runner.py:63} INFO - Started process 9290 to run task
[2024-11-30T06:26:06.374+0000] {task_command.py:426} INFO - Running <TaskInstance: complete-dag.dbt_run manual__2024-11-30T06:25:39.483660+00:00 [running]> on host b09a94790db6
[2024-11-30T06:26:06.511+0000] {taskinstance.py:2648} INFO - Exporting env vars: AIRFLOW_CTX_DAG_OWNER='***' AIRFLOW_CTX_DAG_ID='complete-dag' AIRFLOW_CTX_TASK_ID='dbt_run' AIRFLOW_CTX_EXECUTION_DATE='2024-11-30T06:25:39.483660+00:00' AIRFLOW_CTX_TRY_NUMBER='1' AIRFLOW_CTX_DAG_RUN_ID='manual__2024-11-30T06:25:39.483660+00:00'
[2024-11-30T06:26:06.512+0000] {taskinstance.py:430} INFO - ::endgroup::
[2024-11-30T06:26:06.513+0000] {subprocess.py:63} INFO - Tmp dir root location: /tmp
[2024-11-30T06:26:06.518+0000] {subprocess.py:75} INFO - Running command: ['/usr/bin/bash', '-c', '/home/***/.local/bin/dbt run --profiles-dir /opt/***/dbt --project-dir /opt/***/dbt']
[2024-11-30T06:26:06.534+0000] {subprocess.py:86} INFO - Output:
[2024-11-30T06:26:09.861+0000] {subprocess.py:93} INFO - [0m06:26:09  Running with dbt=1.8.7
[2024-11-30T06:26:11.251+0000] {subprocess.py:93} INFO - [0m06:26:11  Registered adapter: snowflake=1.8.4
[2024-11-30T06:26:11.395+0000] {subprocess.py:93} INFO - [0m06:26:11  Unable to do partial parsing because saved manifest not found. Starting full parse.
[2024-11-30T06:26:12.814+0000] {subprocess.py:93} INFO - [0m06:26:12  [[33mWARNING[0m]: Deprecated functionality
[2024-11-30T06:26:12.816+0000] {subprocess.py:93} INFO - The `tests` config has been renamed to `data_tests`. Please see
[2024-11-30T06:26:12.816+0000] {subprocess.py:93} INFO - https://docs.getdbt.com/docs/build/data-tests#new-data_tests-syntax for more
[2024-11-30T06:26:12.817+0000] {subprocess.py:93} INFO - information.
[2024-11-30T06:26:13.039+0000] {subprocess.py:93} INFO - [0m06:26:13  Encountered an error:
[2024-11-30T06:26:13.040+0000] {subprocess.py:93} INFO - Compilation Error
[2024-11-30T06:26:13.040+0000] {subprocess.py:93} INFO -   Model 'model.project.electricity_data_historical' (models/input/electricity_data_historical.sql) depends on a source named 'raw_data.electricity_data' which was not found
[2024-11-30T06:26:13.913+0000] {subprocess.py:97} INFO - Command exited with return code 2
[2024-11-30T06:26:13.916+0000] {taskinstance.py:441} INFO - ::group::Post task execution logs
[2024-11-30T06:26:13.927+0000] {taskinstance.py:2905} ERROR - Task failed with exception
Traceback (most recent call last):
  File "/home/airflow/.local/lib/python3.12/site-packages/airflow/models/taskinstance.py", line 465, in _execute_task
    result = _execute_callable(context=context, **execute_callable_kwargs)
             ^^^^^^^^^^^^^^^^^^^^^^^^^^^^^^^^^^^^^^^^^^^^^^^^^^^^^^^^^^^^^
  File "/home/airflow/.local/lib/python3.12/site-packages/airflow/models/taskinstance.py", line 432, in _execute_callable
    return execute_callable(context=context, **execute_callable_kwargs)
           ^^^^^^^^^^^^^^^^^^^^^^^^^^^^^^^^^^^^^^^^^^^^^^^^^^^^^^^^^^^^
  File "/home/airflow/.local/lib/python3.12/site-packages/airflow/models/baseoperator.py", line 400, in wrapper
    return func(self, *args, **kwargs)
           ^^^^^^^^^^^^^^^^^^^^^^^^^^^
  File "/home/airflow/.local/lib/python3.12/site-packages/airflow/operators/bash.py", line 243, in execute
    raise AirflowException(
airflow.exceptions.AirflowException: Bash command failed. The command returned a non-zero exit code 2.
[2024-11-30T06:26:13.934+0000] {taskinstance.py:1206} INFO - Marking task as FAILED. dag_id=complete-dag, task_id=dbt_run, run_id=manual__2024-11-30T06:25:39.483660+00:00, execution_date=20241130T062539, start_date=20241130T062606, end_date=20241130T062613
[2024-11-30T06:26:13.959+0000] {standard_task_runner.py:110} ERROR - Failed to execute job 352 for task dbt_run (Bash command failed. The command returned a non-zero exit code 2.; 9290)
[2024-11-30T06:26:13.999+0000] {local_task_job_runner.py:240} INFO - Task exited with return code 1
[2024-11-30T06:26:14.013+0000] {local_task_job_runner.py:222} INFO - ::endgroup::
