[2024-12-05T07:37:57.003+0000] {local_task_job_runner.py:120} INFO - ::group::Pre task execution logs
[2024-12-05T07:37:57.103+0000] {taskinstance.py:2076} INFO - Dependencies all met for dep_context=non-requeueable deps ti=<TaskInstance: dbt-viz-dag.dbt_run manual__2024-12-05T07:37:54.963643+00:00 [queued]>
[2024-12-05T07:37:57.124+0000] {taskinstance.py:2076} INFO - Dependencies all met for dep_context=requeueable deps ti=<TaskInstance: dbt-viz-dag.dbt_run manual__2024-12-05T07:37:54.963643+00:00 [queued]>
[2024-12-05T07:37:57.125+0000] {taskinstance.py:2306} INFO - Starting attempt 1 of 1
[2024-12-05T07:37:57.159+0000] {taskinstance.py:2330} INFO - Executing <Task(BashOperator): dbt_run> on 2024-12-05 07:37:54.963643+00:00
[2024-12-05T07:37:57.170+0000] {standard_task_runner.py:90} INFO - Running: ['***', 'tasks', 'run', 'dbt-viz-dag', 'dbt_run', 'manual__2024-12-05T07:37:54.963643+00:00', '--job-id', '518', '--raw', '--subdir', 'DAGS_FOLDER/dbt-viz-dag.py', '--cfg-path', '/tmp/tmpkqtj9pzw']
[2024-12-05T07:37:57.175+0000] {standard_task_runner.py:91} INFO - Job 518: Subtask dbt_run
[2024-12-05T07:37:57.204+0000] {logging_mixin.py:188} WARNING - /home/***/.local/lib/python3.12/site-packages/***/task/task_runner/standard_task_runner.py:61 DeprecationWarning: This process (pid=1448) is multi-threaded, use of fork() may lead to deadlocks in the child.
[2024-12-05T07:37:57.206+0000] {standard_task_runner.py:63} INFO - Started process 1449 to run task
[2024-12-05T07:37:57.250+0000] {task_command.py:426} INFO - Running <TaskInstance: dbt-viz-dag.dbt_run manual__2024-12-05T07:37:54.963643+00:00 [running]> on host e060654747dc
[2024-12-05T07:37:57.540+0000] {taskinstance.py:2648} INFO - Exporting env vars: AIRFLOW_CTX_DAG_OWNER='***' AIRFLOW_CTX_DAG_ID='dbt-viz-dag' AIRFLOW_CTX_TASK_ID='dbt_run' AIRFLOW_CTX_EXECUTION_DATE='2024-12-05T07:37:54.963643+00:00' AIRFLOW_CTX_TRY_NUMBER='1' AIRFLOW_CTX_DAG_RUN_ID='manual__2024-12-05T07:37:54.963643+00:00'
[2024-12-05T07:37:57.542+0000] {taskinstance.py:430} INFO - ::endgroup::
[2024-12-05T07:37:57.595+0000] {subprocess.py:63} INFO - Tmp dir root location: /tmp
[2024-12-05T07:37:57.601+0000] {subprocess.py:75} INFO - Running command: ['/usr/bin/bash', '-c', '/home/***/.local/bin/dbt run --profiles-dir /opt/***/dbt_viz --project-dir /opt/***/dbt_viz']
[2024-12-05T07:37:57.616+0000] {subprocess.py:86} INFO - Output:
[2024-12-05T07:38:01.216+0000] {subprocess.py:93} INFO - [0m07:38:01  Running with dbt=1.8.7
[2024-12-05T07:38:02.993+0000] {subprocess.py:93} INFO - [0m07:38:02  Registered adapter: snowflake=1.8.4
[2024-12-05T07:38:04.116+0000] {subprocess.py:93} INFO - [0m07:38:04  Encountered an error:
[2024-12-05T07:38:04.117+0000] {subprocess.py:93} INFO - Parsing Error
[2024-12-05T07:38:04.117+0000] {subprocess.py:93} INFO -   at path []: A snapshot configured with the timestamp strategy must specify an updated_at configuration.
[2024-12-05T07:38:05.020+0000] {subprocess.py:97} INFO - Command exited with return code 2
[2024-12-05T07:38:05.024+0000] {taskinstance.py:441} INFO - ::group::Post task execution logs
[2024-12-05T07:38:05.037+0000] {taskinstance.py:2905} ERROR - Task failed with exception
Traceback (most recent call last):
  File "/home/airflow/.local/lib/python3.12/site-packages/airflow/models/taskinstance.py", line 465, in _execute_task
    result = _execute_callable(context=context, **execute_callable_kwargs)
             ^^^^^^^^^^^^^^^^^^^^^^^^^^^^^^^^^^^^^^^^^^^^^^^^^^^^^^^^^^^^^
  File "/home/airflow/.local/lib/python3.12/site-packages/airflow/models/taskinstance.py", line 432, in _execute_callable
    return execute_callable(context=context, **execute_callable_kwargs)
           ^^^^^^^^^^^^^^^^^^^^^^^^^^^^^^^^^^^^^^^^^^^^^^^^^^^^^^^^^^^^
  File "/home/airflow/.local/lib/python3.12/site-packages/airflow/models/baseoperator.py", line 400, in wrapper
    return func(self, *args, **kwargs)
           ^^^^^^^^^^^^^^^^^^^^^^^^^^^
  File "/home/airflow/.local/lib/python3.12/site-packages/airflow/operators/bash.py", line 243, in execute
    raise AirflowException(
airflow.exceptions.AirflowException: Bash command failed. The command returned a non-zero exit code 2.
[2024-12-05T07:38:05.046+0000] {taskinstance.py:1206} INFO - Marking task as FAILED. dag_id=dbt-viz-dag, task_id=dbt_run, run_id=manual__2024-12-05T07:37:54.963643+00:00, execution_date=20241205T073754, start_date=20241205T073757, end_date=20241205T073805
[2024-12-05T07:38:05.065+0000] {standard_task_runner.py:110} ERROR - Failed to execute job 518 for task dbt_run (Bash command failed. The command returned a non-zero exit code 2.; 1449)
[2024-12-05T07:38:05.086+0000] {local_task_job_runner.py:240} INFO - Task exited with return code 1
[2024-12-05T07:38:05.117+0000] {taskinstance.py:3498} INFO - 0 downstream tasks scheduled from follow-on schedule check
[2024-12-05T07:38:05.126+0000] {local_task_job_runner.py:222} INFO - ::endgroup::
