[2024-11-12T03:50:21.549+0000] {local_task_job_runner.py:120} INFO - ::group::Pre task execution logs
[2024-11-12T03:50:21.614+0000] {taskinstance.py:2076} INFO - Dependencies all met for dep_context=non-requeueable deps ti=<TaskInstance: BuildELT_dbt.dbt_test manual__2024-11-12T03:49:58.116185+00:00 [queued]>
[2024-11-12T03:50:21.632+0000] {taskinstance.py:2076} INFO - Dependencies all met for dep_context=requeueable deps ti=<TaskInstance: BuildELT_dbt.dbt_test manual__2024-11-12T03:49:58.116185+00:00 [queued]>
[2024-11-12T03:50:21.633+0000] {taskinstance.py:2306} INFO - Starting attempt 1 of 1
[2024-11-12T03:50:21.661+0000] {taskinstance.py:2330} INFO - Executing <Task(BashOperator): dbt_test> on 2024-11-12 03:49:58.116185+00:00
[2024-11-12T03:50:21.708+0000] {standard_task_runner.py:90} INFO - Running: ['***', 'tasks', 'run', 'BuildELT_dbt', 'dbt_test', 'manual__2024-11-12T03:49:58.116185+00:00', '--job-id', '153', '--raw', '--subdir', 'DAGS_FOLDER/build_elt_with_dbt.py', '--cfg-path', '/tmp/tmp4epy81v9']
[2024-11-12T03:50:21.711+0000] {standard_task_runner.py:91} INFO - Job 153: Subtask dbt_test
[2024-11-12T03:50:21.716+0000] {logging_mixin.py:188} WARNING - /home/***/.local/lib/python3.12/site-packages/***/task/task_runner/standard_task_runner.py:61 DeprecationWarning: This process (pid=2904) is multi-threaded, use of fork() may lead to deadlocks in the child.
[2024-11-12T03:50:21.718+0000] {standard_task_runner.py:63} INFO - Started process 2905 to run task
[2024-11-12T03:50:21.792+0000] {task_command.py:426} INFO - Running <TaskInstance: BuildELT_dbt.dbt_test manual__2024-11-12T03:49:58.116185+00:00 [running]> on host e9e87141c083
[2024-11-12T03:50:22.018+0000] {taskinstance.py:2648} INFO - Exporting env vars: AIRFLOW_CTX_DAG_OWNER='***' AIRFLOW_CTX_DAG_ID='BuildELT_dbt' AIRFLOW_CTX_TASK_ID='dbt_test' AIRFLOW_CTX_EXECUTION_DATE='2024-11-12T03:49:58.116185+00:00' AIRFLOW_CTX_TRY_NUMBER='1' AIRFLOW_CTX_DAG_RUN_ID='manual__2024-11-12T03:49:58.116185+00:00'
[2024-11-12T03:50:22.020+0000] {taskinstance.py:430} INFO - ::endgroup::
[2024-11-12T03:50:22.036+0000] {subprocess.py:63} INFO - Tmp dir root location: /tmp
[2024-11-12T03:50:22.040+0000] {subprocess.py:75} INFO - Running command: ['/usr/bin/bash', '-c', '/home/***/.local/bin/dbt test --profiles-dir /opt/***/dbt --project-dir /opt/***/dbt']
[2024-11-12T03:50:22.054+0000] {subprocess.py:86} INFO - Output:
[2024-11-12T03:50:25.059+0000] {subprocess.py:93} INFO - [0m03:50:25  Running with dbt=1.8.7
[2024-11-12T03:50:26.251+0000] {subprocess.py:93} INFO - [0m03:50:26  Registered adapter: snowflake=1.8.4
[2024-11-12T03:50:27.612+0000] {subprocess.py:93} INFO - [0m03:50:27  Found 5 models, 1 snapshot, 1 test, 2 sources, 459 macros
[2024-11-12T03:50:27.619+0000] {subprocess.py:93} INFO - [0m03:50:27
[2024-11-12T03:50:29.071+0000] {subprocess.py:93} INFO - [0m03:50:29  Concurrency: 1 threads (target='dev')
[2024-11-12T03:50:29.073+0000] {subprocess.py:93} INFO - [0m03:50:29
[2024-11-12T03:50:29.101+0000] {subprocess.py:93} INFO - [0m03:50:29  1 of 1 START test dbt_utils_unique_combination_of_columns_stock_indicators_date__symbol  [RUN]
[2024-11-12T03:50:29.202+0000] {subprocess.py:93} INFO - [0m03:50:29  1 of 1 ERROR dbt_utils_unique_combination_of_columns_stock_indicators_date__symbol  [[31mERROR[0m in 0.10s]
[2024-11-12T03:50:29.216+0000] {subprocess.py:93} INFO - [0m03:50:29
[2024-11-12T03:50:29.217+0000] {subprocess.py:93} INFO - [0m03:50:29  Finished running 1 test in 0 hours 0 minutes and 1.59 seconds (1.59s).
[2024-11-12T03:50:29.333+0000] {subprocess.py:93} INFO - [0m03:50:29
[2024-11-12T03:50:29.334+0000] {subprocess.py:93} INFO - [0m03:50:29  [31mCompleted with 1 error and 0 warnings:[0m
[2024-11-12T03:50:29.337+0000] {subprocess.py:93} INFO - [0m03:50:29
[2024-11-12T03:50:29.338+0000] {subprocess.py:93} INFO - [0m03:50:29    Compilation Error in test dbt_utils_unique_combination_of_columns_stock_indicators_date__symbol (models/schema.yml)
[2024-11-12T03:50:29.339+0000] {subprocess.py:93} INFO -   'dbt_utils' is undefined. This can happen when calling a macro that does not exist. Check for typos and/or install package dependencies with "dbt deps".
[2024-11-12T03:50:29.340+0000] {subprocess.py:93} INFO - [0m03:50:29
[2024-11-12T03:50:29.341+0000] {subprocess.py:93} INFO - [0m03:50:29  Done. PASS=0 WARN=0 ERROR=1 SKIP=0 TOTAL=1
[2024-11-12T03:50:30.183+0000] {subprocess.py:97} INFO - Command exited with return code 1
[2024-11-12T03:50:30.185+0000] {taskinstance.py:441} INFO - ::group::Post task execution logs
[2024-11-12T03:50:30.201+0000] {taskinstance.py:2905} ERROR - Task failed with exception
Traceback (most recent call last):
  File "/home/airflow/.local/lib/python3.12/site-packages/airflow/models/taskinstance.py", line 465, in _execute_task
    result = _execute_callable(context=context, **execute_callable_kwargs)
             ^^^^^^^^^^^^^^^^^^^^^^^^^^^^^^^^^^^^^^^^^^^^^^^^^^^^^^^^^^^^^
  File "/home/airflow/.local/lib/python3.12/site-packages/airflow/models/taskinstance.py", line 432, in _execute_callable
    return execute_callable(context=context, **execute_callable_kwargs)
           ^^^^^^^^^^^^^^^^^^^^^^^^^^^^^^^^^^^^^^^^^^^^^^^^^^^^^^^^^^^^
  File "/home/airflow/.local/lib/python3.12/site-packages/airflow/models/baseoperator.py", line 400, in wrapper
    return func(self, *args, **kwargs)
           ^^^^^^^^^^^^^^^^^^^^^^^^^^^
  File "/home/airflow/.local/lib/python3.12/site-packages/airflow/operators/bash.py", line 243, in execute
    raise AirflowException(
airflow.exceptions.AirflowException: Bash command failed. The command returned a non-zero exit code 1.
[2024-11-12T03:50:30.223+0000] {taskinstance.py:1206} INFO - Marking task as FAILED. dag_id=BuildELT_dbt, task_id=dbt_test, run_id=manual__2024-11-12T03:49:58.116185+00:00, execution_date=20241112T034958, start_date=20241112T035021, end_date=20241112T035030
[2024-11-12T03:50:30.246+0000] {standard_task_runner.py:110} ERROR - Failed to execute job 153 for task dbt_test (Bash command failed. The command returned a non-zero exit code 1.; 2905)
[2024-11-12T03:50:30.260+0000] {local_task_job_runner.py:240} INFO - Task exited with return code 1
[2024-11-12T03:50:30.287+0000] {taskinstance.py:3498} INFO - 0 downstream tasks scheduled from follow-on schedule check
[2024-11-12T03:50:30.293+0000] {local_task_job_runner.py:222} INFO - ::endgroup::
