[2024-11-28T20:23:47.196+0000] {local_task_job_runner.py:120} INFO - ::group::Pre task execution logs
[2024-11-28T20:23:47.248+0000] {taskinstance.py:2076} INFO - Dependencies all met for dep_context=non-requeueable deps ti=<TaskInstance: Weather_Forecast.load_weather_data_to_snowflake manual__2024-11-28T20:23:34.500806+00:00 [queued]>
[2024-11-28T20:23:47.257+0000] {taskinstance.py:2076} INFO - Dependencies all met for dep_context=requeueable deps ti=<TaskInstance: Weather_Forecast.load_weather_data_to_snowflake manual__2024-11-28T20:23:34.500806+00:00 [queued]>
[2024-11-28T20:23:47.265+0000] {taskinstance.py:2306} INFO - Starting attempt 1 of 1
[2024-11-28T20:23:47.335+0000] {taskinstance.py:2330} INFO - Executing <Task(_PythonDecoratedOperator): load_weather_data_to_snowflake> on 2024-11-28 20:23:34.500806+00:00
[2024-11-28T20:23:47.387+0000] {standard_task_runner.py:90} INFO - Running: ['***', 'tasks', 'run', 'Weather_Forecast', 'load_weather_data_to_snowflake', 'manual__2024-11-28T20:23:34.500806+00:00', '--job-id', '238', '--raw', '--subdir', 'DAGS_FOLDER/weather_forecast_dag.py', '--cfg-path', '/tmp/tmp8x6juaw0']
[2024-11-28T20:23:47.390+0000] {standard_task_runner.py:91} INFO - Job 238: Subtask load_weather_data_to_snowflake
[2024-11-28T20:23:47.390+0000] {logging_mixin.py:188} WARNING - /home/***/.local/lib/python3.12/site-packages/***/task/task_runner/standard_task_runner.py:61 DeprecationWarning: This process (pid=963) is multi-threaded, use of fork() may lead to deadlocks in the child.
[2024-11-28T20:23:47.391+0000] {standard_task_runner.py:63} INFO - Started process 966 to run task
[2024-11-28T20:23:47.538+0000] {task_command.py:426} INFO - Running <TaskInstance: Weather_Forecast.load_weather_data_to_snowflake manual__2024-11-28T20:23:34.500806+00:00 [running]> on host fd43cd87157f
[2024-11-28T20:23:48.416+0000] {taskinstance.py:2648} INFO - Exporting env vars: AIRFLOW_CTX_DAG_OWNER='***' AIRFLOW_CTX_DAG_ID='Weather_Forecast' AIRFLOW_CTX_TASK_ID='load_weather_data_to_snowflake' AIRFLOW_CTX_EXECUTION_DATE='2024-11-28T20:23:34.500806+00:00' AIRFLOW_CTX_TRY_NUMBER='1' AIRFLOW_CTX_DAG_RUN_ID='manual__2024-11-28T20:23:34.500806+00:00'
[2024-11-28T20:23:48.429+0000] {taskinstance.py:430} INFO - ::endgroup::
[2024-11-28T20:23:48.481+0000] {base.py:84} INFO - Using connection ID 'snowflake_conn' for task execution.
[2024-11-28T20:23:48.494+0000] {connection.py:399} INFO - Snowflake Connector for Python Version: 3.10.0, Python Version: 3.12.3, Platform: Linux-5.15.153.1-microsoft-standard-WSL2-x86_64-with-glibc2.36
[2024-11-28T20:23:48.495+0000] {connection.py:1239} INFO - This connection is in OCSP Fail Open Mode. TLS Certificates would be checked for validity and revocation status. Any other Certificate Revocation related exceptions or OCSP Responder failures would be disregarded in favor of connectivity.
[2024-11-28T20:23:49.375+0000] {cursor.py:1149} INFO - Number of results in first chunk: 1
[2024-11-28T20:23:49.877+0000] {cursor.py:1149} INFO - Number of results in first chunk: 1
[2024-11-28T20:23:49.883+0000] {logging_mixin.py:188} WARNING - /opt/***/dags/weather_forecast_dag.py:62 FutureWarning: DataFrame.applymap has been deprecated. Use DataFrame.map instead.
[2024-11-28T20:23:49.896+0000] {logging_mixin.py:188} INFO -          Date  temperature_2m_max  ...  windspeed_10m_max  avg_temperature
0  2024-11-28                12.2  ...               23.7             6.50
1  2024-11-29                14.7  ...               17.6             8.85
2  2024-11-30                14.7  ...               14.6            10.50
3  2024-12-01                14.2  ...               25.0             9.40
4  2024-12-02                 6.5  ...               20.2             2.80

[5 rows x 7 columns]
[2024-11-28T20:23:50.182+0000] {cursor.py:1149} INFO - Number of results in first chunk: 1
[2024-11-28T20:23:50.183+0000] {logging_mixin.py:188} INFO - Error inserting data: 002020 (21S01): 01b8ae27-0004-3987-0002-5953000383f2: SQL compilation error:
Insert value list does not match column list expecting 5 but got 7
[2024-11-28T20:23:50.183+0000] {connection.py:762} INFO - closed
[2024-11-28T20:23:50.265+0000] {connection.py:768} INFO - No async queries seem to be running, deleting session
[2024-11-28T20:23:50.353+0000] {taskinstance.py:441} INFO - ::group::Post task execution logs
[2024-11-28T20:23:50.354+0000] {taskinstance.py:2905} ERROR - Task failed with exception
Traceback (most recent call last):
  File "/home/airflow/.local/lib/python3.12/site-packages/airflow/models/taskinstance.py", line 465, in _execute_task
    result = _execute_callable(context=context, **execute_callable_kwargs)
             ^^^^^^^^^^^^^^^^^^^^^^^^^^^^^^^^^^^^^^^^^^^^^^^^^^^^^^^^^^^^^
  File "/home/airflow/.local/lib/python3.12/site-packages/airflow/models/taskinstance.py", line 432, in _execute_callable
    return execute_callable(context=context, **execute_callable_kwargs)
           ^^^^^^^^^^^^^^^^^^^^^^^^^^^^^^^^^^^^^^^^^^^^^^^^^^^^^^^^^^^^
  File "/home/airflow/.local/lib/python3.12/site-packages/airflow/models/baseoperator.py", line 400, in wrapper
    return func(self, *args, **kwargs)
           ^^^^^^^^^^^^^^^^^^^^^^^^^^^
  File "/home/airflow/.local/lib/python3.12/site-packages/airflow/decorators/base.py", line 265, in execute
    return_value = super().execute(context)
                   ^^^^^^^^^^^^^^^^^^^^^^^^
  File "/home/airflow/.local/lib/python3.12/site-packages/airflow/models/baseoperator.py", line 400, in wrapper
    return func(self, *args, **kwargs)
           ^^^^^^^^^^^^^^^^^^^^^^^^^^^
  File "/home/airflow/.local/lib/python3.12/site-packages/airflow/operators/python.py", line 235, in execute
    return_value = self.execute_callable()
                   ^^^^^^^^^^^^^^^^^^^^^^^
  File "/home/airflow/.local/lib/python3.12/site-packages/airflow/operators/python.py", line 252, in execute_callable
    return self.python_callable(*self.op_args, **self.op_kwargs)
           ^^^^^^^^^^^^^^^^^^^^^^^^^^^^^^^^^^^^^^^^^^^^^^^^^^^^^
  File "/opt/airflow/dags/weather_forecast_dag.py", line 91, in load_weather_data_to_snowflake
    cursor.executemany(insert_query, weather_data)
  File "/home/airflow/.local/lib/python3.12/site-packages/snowflake/connector/cursor.py", line 1387, in executemany
    self.execute(command, **kwargs)
  File "/home/airflow/.local/lib/python3.12/site-packages/snowflake/connector/cursor.py", line 1080, in execute
    Error.errorhandler_wrapper(self.connection, self, error_class, errvalue)
  File "/home/airflow/.local/lib/python3.12/site-packages/snowflake/connector/errors.py", line 290, in errorhandler_wrapper
    handed_over = Error.hand_to_other_handler(
                  ^^^^^^^^^^^^^^^^^^^^^^^^^^^^
  File "/home/airflow/.local/lib/python3.12/site-packages/snowflake/connector/errors.py", line 345, in hand_to_other_handler
    cursor.errorhandler(connection, cursor, error_class, error_value)
  File "/home/airflow/.local/lib/python3.12/site-packages/snowflake/connector/errors.py", line 221, in default_errorhandler
    raise error_class(
snowflake.connector.errors.ProgrammingError: 002020 (21S01): 01b8ae27-0004-3987-0002-5953000383f2: SQL compilation error:
Insert value list does not match column list expecting 5 but got 7
[2024-11-28T20:23:50.367+0000] {taskinstance.py:1206} INFO - Marking task as FAILED. dag_id=Weather_Forecast, task_id=load_weather_data_to_snowflake, run_id=manual__2024-11-28T20:23:34.500806+00:00, execution_date=20241128T202334, start_date=20241128T202347, end_date=20241128T202350
[2024-11-28T20:23:50.388+0000] {standard_task_runner.py:110} ERROR - Failed to execute job 238 for task load_weather_data_to_snowflake (002020 (21S01): 01b8ae27-0004-3987-0002-5953000383f2: SQL compilation error:
Insert value list does not match column list expecting 5 but got 7; 966)
[2024-11-28T20:23:50.419+0000] {local_task_job_runner.py:240} INFO - Task exited with return code 1
[2024-11-28T20:23:50.439+0000] {taskinstance.py:3498} INFO - 0 downstream tasks scheduled from follow-on schedule check
[2024-11-28T20:23:50.443+0000] {local_task_job_runner.py:222} INFO - ::endgroup::
