[2024-11-30T08:32:04.012+0000] {local_task_job_runner.py:120} INFO - ::group::Pre task execution logs
[2024-11-30T08:32:04.090+0000] {taskinstance.py:2076} INFO - Dependencies all met for dep_context=non-requeueable deps ti=<TaskInstance: dbt-viz-dag.dbt_run manual__2024-11-30T08:32:02.637878+00:00 [queued]>
[2024-11-30T08:32:04.118+0000] {taskinstance.py:2076} INFO - Dependencies all met for dep_context=requeueable deps ti=<TaskInstance: dbt-viz-dag.dbt_run manual__2024-11-30T08:32:02.637878+00:00 [queued]>
[2024-11-30T08:32:04.120+0000] {taskinstance.py:2306} INFO - Starting attempt 1 of 1
[2024-11-30T08:32:04.144+0000] {taskinstance.py:2330} INFO - Executing <Task(BashOperator): dbt_run> on 2024-11-30 08:32:02.637878+00:00
[2024-11-30T08:32:04.161+0000] {standard_task_runner.py:90} INFO - Running: ['***', 'tasks', 'run', 'dbt-viz-dag', 'dbt_run', 'manual__2024-11-30T08:32:02.637878+00:00', '--job-id', '410', '--raw', '--subdir', 'DAGS_FOLDER/dbt-viz-dag.py', '--cfg-path', '/tmp/tmpnwgx841f']
[2024-11-30T08:32:04.164+0000] {standard_task_runner.py:91} INFO - Job 410: Subtask dbt_run
[2024-11-30T08:32:04.164+0000] {logging_mixin.py:188} WARNING - /home/***/.local/lib/python3.12/site-packages/***/task/task_runner/standard_task_runner.py:61 DeprecationWarning: This process (pid=2014) is multi-threaded, use of fork() may lead to deadlocks in the child.
[2024-11-30T08:32:04.165+0000] {standard_task_runner.py:63} INFO - Started process 2017 to run task
[2024-11-30T08:32:04.229+0000] {task_command.py:426} INFO - Running <TaskInstance: dbt-viz-dag.dbt_run manual__2024-11-30T08:32:02.637878+00:00 [running]> on host e060654747dc
[2024-11-30T08:32:04.515+0000] {taskinstance.py:2648} INFO - Exporting env vars: AIRFLOW_CTX_DAG_OWNER='***' AIRFLOW_CTX_DAG_ID='dbt-viz-dag' AIRFLOW_CTX_TASK_ID='dbt_run' AIRFLOW_CTX_EXECUTION_DATE='2024-11-30T08:32:02.637878+00:00' AIRFLOW_CTX_TRY_NUMBER='1' AIRFLOW_CTX_DAG_RUN_ID='manual__2024-11-30T08:32:02.637878+00:00'
[2024-11-30T08:32:04.517+0000] {taskinstance.py:430} INFO - ::endgroup::
[2024-11-30T08:32:04.570+0000] {subprocess.py:63} INFO - Tmp dir root location: /tmp
[2024-11-30T08:32:04.585+0000] {subprocess.py:75} INFO - Running command: ['/usr/bin/bash', '-c', '/home/***/.local/bin/dbt run --profiles-dir /opt/***/dbt_viz --project-dir /opt/***/dbt_viz']
[2024-11-30T08:32:04.604+0000] {subprocess.py:86} INFO - Output:
[2024-11-30T08:32:08.277+0000] {subprocess.py:93} INFO - [0m08:32:08  Running with dbt=1.8.7
[2024-11-30T08:32:10.625+0000] {subprocess.py:93} INFO - [0m08:32:10  Registered adapter: snowflake=1.8.4
[2024-11-30T08:32:11.478+0000] {subprocess.py:93} INFO - [0m08:32:11  Found 4 models, 1 test, 3 sources, 459 macros
[2024-11-30T08:32:11.482+0000] {subprocess.py:93} INFO - [0m08:32:11
[2024-11-30T08:32:13.740+0000] {subprocess.py:93} INFO - [0m08:32:13  Concurrency: 1 threads (target='dev')
[2024-11-30T08:32:13.741+0000] {subprocess.py:93} INFO - [0m08:32:13
[2024-11-30T08:32:13.790+0000] {subprocess.py:93} INFO - [0m08:32:13  1 of 2 START sql table model analytics.energy_historical_forecast_data ......... [RUN]
[2024-11-30T08:32:15.541+0000] {subprocess.py:93} INFO - [0m08:32:15  1 of 2 OK created sql table model analytics.energy_historical_forecast_data .... [[32mSUCCESS 1[0m in 1.75s]
[2024-11-30T08:32:15.544+0000] {subprocess.py:93} INFO - [0m08:32:15  2 of 2 START sql table model analytics.energy_demand_final_data ................ [RUN]
[2024-11-30T08:32:16.412+0000] {subprocess.py:93} INFO - [0m08:32:16  2 of 2 ERROR creating sql table model analytics.energy_demand_final_data ....... [[31mERROR[0m in 0.86s]
[2024-11-30T08:32:16.418+0000] {subprocess.py:93} INFO - [0m08:32:16
[2024-11-30T08:32:16.419+0000] {subprocess.py:93} INFO - [0m08:32:16  Finished running 2 table models in 0 hours 0 minutes and 4.93 seconds (4.93s).
[2024-11-30T08:32:16.472+0000] {subprocess.py:93} INFO - [0m08:32:16
[2024-11-30T08:32:16.473+0000] {subprocess.py:93} INFO - [0m08:32:16  [31mCompleted with 1 error and 0 warnings:[0m
[2024-11-30T08:32:16.474+0000] {subprocess.py:93} INFO - [0m08:32:16
[2024-11-30T08:32:16.475+0000] {subprocess.py:93} INFO - [0m08:32:16    Database Error in model energy_demand_final_data (models/output/energy_demand_final_data.sql)
[2024-11-30T08:32:16.475+0000] {subprocess.py:93} INFO -   000904 (42000): SQL compilation error: error line 26 at position 43
[2024-11-30T08:32:16.476+0000] {subprocess.py:93} INFO -   invalid identifier '"Actual"'
[2024-11-30T08:32:16.477+0000] {subprocess.py:93} INFO -   compiled code at target/run/project/models/output/energy_demand_final_data.sql
[2024-11-30T08:32:16.478+0000] {subprocess.py:93} INFO - [0m08:32:16
[2024-11-30T08:32:16.478+0000] {subprocess.py:93} INFO - [0m08:32:16  Done. PASS=1 WARN=0 ERROR=1 SKIP=0 TOTAL=2
[2024-11-30T08:32:17.214+0000] {subprocess.py:97} INFO - Command exited with return code 1
[2024-11-30T08:32:17.217+0000] {taskinstance.py:441} INFO - ::group::Post task execution logs
[2024-11-30T08:32:17.229+0000] {taskinstance.py:2905} ERROR - Task failed with exception
Traceback (most recent call last):
  File "/home/airflow/.local/lib/python3.12/site-packages/airflow/models/taskinstance.py", line 465, in _execute_task
    result = _execute_callable(context=context, **execute_callable_kwargs)
             ^^^^^^^^^^^^^^^^^^^^^^^^^^^^^^^^^^^^^^^^^^^^^^^^^^^^^^^^^^^^^
  File "/home/airflow/.local/lib/python3.12/site-packages/airflow/models/taskinstance.py", line 432, in _execute_callable
    return execute_callable(context=context, **execute_callable_kwargs)
           ^^^^^^^^^^^^^^^^^^^^^^^^^^^^^^^^^^^^^^^^^^^^^^^^^^^^^^^^^^^^
  File "/home/airflow/.local/lib/python3.12/site-packages/airflow/models/baseoperator.py", line 400, in wrapper
    return func(self, *args, **kwargs)
           ^^^^^^^^^^^^^^^^^^^^^^^^^^^
  File "/home/airflow/.local/lib/python3.12/site-packages/airflow/operators/bash.py", line 243, in execute
    raise AirflowException(
airflow.exceptions.AirflowException: Bash command failed. The command returned a non-zero exit code 1.
[2024-11-30T08:32:17.245+0000] {taskinstance.py:1206} INFO - Marking task as FAILED. dag_id=dbt-viz-dag, task_id=dbt_run, run_id=manual__2024-11-30T08:32:02.637878+00:00, execution_date=20241130T083202, start_date=20241130T083204, end_date=20241130T083217
[2024-11-30T08:32:17.269+0000] {standard_task_runner.py:110} ERROR - Failed to execute job 410 for task dbt_run (Bash command failed. The command returned a non-zero exit code 1.; 2017)
[2024-11-30T08:32:17.284+0000] {local_task_job_runner.py:240} INFO - Task exited with return code 1
[2024-11-30T08:32:17.307+0000] {taskinstance.py:3498} INFO - 0 downstream tasks scheduled from follow-on schedule check
[2024-11-30T08:32:17.313+0000] {local_task_job_runner.py:222} INFO - ::endgroup::
