[2024-11-13T18:43:45.504+0000] {local_task_job_runner.py:120} INFO - ::group::Pre task execution logs
[2024-11-13T18:43:45.576+0000] {taskinstance.py:2076} INFO - Dependencies all met for dep_context=non-requeueable deps ti=<TaskInstance: BuildELT_dbt.dbt_run manual__2024-11-13T18:43:44.198744+00:00 [queued]>
[2024-11-13T18:43:45.594+0000] {taskinstance.py:2076} INFO - Dependencies all met for dep_context=requeueable deps ti=<TaskInstance: BuildELT_dbt.dbt_run manual__2024-11-13T18:43:44.198744+00:00 [queued]>
[2024-11-13T18:43:45.596+0000] {taskinstance.py:2306} INFO - Starting attempt 1 of 1
[2024-11-13T18:43:45.620+0000] {taskinstance.py:2330} INFO - Executing <Task(BashOperator): dbt_run> on 2024-11-13 18:43:44.198744+00:00
[2024-11-13T18:43:45.631+0000] {standard_task_runner.py:90} INFO - Running: ['***', 'tasks', 'run', 'BuildELT_dbt', 'dbt_run', 'manual__2024-11-13T18:43:44.198744+00:00', '--job-id', '178', '--raw', '--subdir', 'DAGS_FOLDER/build_elt_with_dbt.py', '--cfg-path', '/tmp/tmp3hpgt1iy']
[2024-11-13T18:43:45.634+0000] {standard_task_runner.py:91} INFO - Job 178: Subtask dbt_run
[2024-11-13T18:43:45.635+0000] {logging_mixin.py:188} WARNING - /home/***/.local/lib/python3.12/site-packages/***/task/task_runner/standard_task_runner.py:61 DeprecationWarning: This process (pid=1131) is multi-threaded, use of fork() may lead to deadlocks in the child.
[2024-11-13T18:43:45.636+0000] {standard_task_runner.py:63} INFO - Started process 1132 to run task
[2024-11-13T18:43:45.692+0000] {task_command.py:426} INFO - Running <TaskInstance: BuildELT_dbt.dbt_run manual__2024-11-13T18:43:44.198744+00:00 [running]> on host d7a7afbedfaf
[2024-11-13T18:43:45.856+0000] {taskinstance.py:2648} INFO - Exporting env vars: AIRFLOW_CTX_DAG_OWNER='***' AIRFLOW_CTX_DAG_ID='BuildELT_dbt' AIRFLOW_CTX_TASK_ID='dbt_run' AIRFLOW_CTX_EXECUTION_DATE='2024-11-13T18:43:44.198744+00:00' AIRFLOW_CTX_TRY_NUMBER='1' AIRFLOW_CTX_DAG_RUN_ID='manual__2024-11-13T18:43:44.198744+00:00'
[2024-11-13T18:43:45.858+0000] {taskinstance.py:430} INFO - ::endgroup::
[2024-11-13T18:43:45.872+0000] {subprocess.py:63} INFO - Tmp dir root location: /tmp
[2024-11-13T18:43:45.874+0000] {subprocess.py:75} INFO - Running command: ['/usr/bin/bash', '-c', '/home/***/.local/bin/dbt run --profiles-dir /opt/***/dbt --project-dir /opt/***/dbt']
[2024-11-13T18:43:45.885+0000] {subprocess.py:86} INFO - Output:
[2024-11-13T18:43:48.287+0000] {subprocess.py:93} INFO - [0m18:43:48  Running with dbt=1.8.7
[2024-11-13T18:43:49.519+0000] {subprocess.py:93} INFO - [0m18:43:49  Registered adapter: snowflake=1.8.4
[2024-11-13T18:43:50.437+0000] {subprocess.py:93} INFO - [0m18:43:50  Found 6 models, 1 snapshot, 2 data tests, 2 sources, 459 macros
[2024-11-13T18:43:50.442+0000] {subprocess.py:93} INFO - [0m18:43:50
[2024-11-13T18:43:52.863+0000] {subprocess.py:93} INFO - [0m18:43:52  Concurrency: 1 threads (target='dev')
[2024-11-13T18:43:52.864+0000] {subprocess.py:93} INFO - [0m18:43:52
[2024-11-13T18:43:52.965+0000] {subprocess.py:93} INFO - [0m18:43:52  1 of 1 START sql table model analytics.stock_indicators ........................ [RUN]
[2024-11-13T18:43:53.808+0000] {subprocess.py:93} INFO - [0m18:43:53  1 of 1 ERROR creating sql table model analytics.stock_indicators ............... [[31mERROR[0m in 0.84s]
[2024-11-13T18:43:53.813+0000] {subprocess.py:93} INFO - [0m18:43:53
[2024-11-13T18:43:53.814+0000] {subprocess.py:93} INFO - [0m18:43:53  Finished running 1 table model in 0 hours 0 minutes and 3.37 seconds (3.37s).
[2024-11-13T18:43:53.870+0000] {subprocess.py:93} INFO - [0m18:43:53
[2024-11-13T18:43:53.871+0000] {subprocess.py:93} INFO - [0m18:43:53  [31mCompleted with 1 error and 0 warnings:[0m
[2024-11-13T18:43:53.872+0000] {subprocess.py:93} INFO - [0m18:43:53
[2024-11-13T18:43:53.873+0000] {subprocess.py:93} INFO - [0m18:43:53    Database Error in model stock_indicators (models/output/stock_indicators.sql)
[2024-11-13T18:43:53.874+0000] {subprocess.py:93} INFO -   001003 (42000): SQL compilation error:
[2024-11-13T18:43:53.874+0000] {subprocess.py:93} INFO -   syntax error line 118 at position 8 unexpected ';'.
[2024-11-13T18:43:53.874+0000] {subprocess.py:93} INFO -   compiled code at target/run/lab2/models/output/stock_indicators.sql
[2024-11-13T18:43:53.875+0000] {subprocess.py:93} INFO - [0m18:43:53
[2024-11-13T18:43:53.875+0000] {subprocess.py:93} INFO - [0m18:43:53  Done. PASS=0 WARN=0 ERROR=1 SKIP=0 TOTAL=1
[2024-11-13T18:43:54.664+0000] {subprocess.py:97} INFO - Command exited with return code 1
[2024-11-13T18:43:54.666+0000] {taskinstance.py:441} INFO - ::group::Post task execution logs
[2024-11-13T18:43:54.676+0000] {taskinstance.py:2905} ERROR - Task failed with exception
Traceback (most recent call last):
  File "/home/airflow/.local/lib/python3.12/site-packages/airflow/models/taskinstance.py", line 465, in _execute_task
    result = _execute_callable(context=context, **execute_callable_kwargs)
             ^^^^^^^^^^^^^^^^^^^^^^^^^^^^^^^^^^^^^^^^^^^^^^^^^^^^^^^^^^^^^
  File "/home/airflow/.local/lib/python3.12/site-packages/airflow/models/taskinstance.py", line 432, in _execute_callable
    return execute_callable(context=context, **execute_callable_kwargs)
           ^^^^^^^^^^^^^^^^^^^^^^^^^^^^^^^^^^^^^^^^^^^^^^^^^^^^^^^^^^^^
  File "/home/airflow/.local/lib/python3.12/site-packages/airflow/models/baseoperator.py", line 400, in wrapper
    return func(self, *args, **kwargs)
           ^^^^^^^^^^^^^^^^^^^^^^^^^^^
  File "/home/airflow/.local/lib/python3.12/site-packages/airflow/operators/bash.py", line 243, in execute
    raise AirflowException(
airflow.exceptions.AirflowException: Bash command failed. The command returned a non-zero exit code 1.
[2024-11-13T18:43:54.681+0000] {taskinstance.py:1206} INFO - Marking task as FAILED. dag_id=BuildELT_dbt, task_id=dbt_run, run_id=manual__2024-11-13T18:43:44.198744+00:00, execution_date=20241113T184344, start_date=20241113T184345, end_date=20241113T184354
[2024-11-13T18:43:54.698+0000] {standard_task_runner.py:110} ERROR - Failed to execute job 178 for task dbt_run (Bash command failed. The command returned a non-zero exit code 1.; 1132)
[2024-11-13T18:43:54.728+0000] {local_task_job_runner.py:240} INFO - Task exited with return code 1
[2024-11-13T18:43:54.757+0000] {taskinstance.py:3498} INFO - 0 downstream tasks scheduled from follow-on schedule check
[2024-11-13T18:43:54.765+0000] {local_task_job_runner.py:222} INFO - ::endgroup::
