[2024-11-13T18:52:07.969+0000] {local_task_job_runner.py:120} INFO - ::group::Pre task execution logs
[2024-11-13T18:52:08.020+0000] {taskinstance.py:2076} INFO - Dependencies all met for dep_context=non-requeueable deps ti=<TaskInstance: BuildELT_dbt.dbt_run manual__2024-11-13T18:52:06.899530+00:00 [queued]>
[2024-11-13T18:52:08.031+0000] {taskinstance.py:2076} INFO - Dependencies all met for dep_context=requeueable deps ti=<TaskInstance: BuildELT_dbt.dbt_run manual__2024-11-13T18:52:06.899530+00:00 [queued]>
[2024-11-13T18:52:08.033+0000] {taskinstance.py:2306} INFO - Starting attempt 1 of 1
[2024-11-13T18:52:08.060+0000] {taskinstance.py:2330} INFO - Executing <Task(BashOperator): dbt_run> on 2024-11-13 18:52:06.899530+00:00
[2024-11-13T18:52:08.081+0000] {standard_task_runner.py:90} INFO - Running: ['***', 'tasks', 'run', 'BuildELT_dbt', 'dbt_run', 'manual__2024-11-13T18:52:06.899530+00:00', '--job-id', '179', '--raw', '--subdir', 'DAGS_FOLDER/build_elt_with_dbt.py', '--cfg-path', '/tmp/tmpm8lwn77u']
[2024-11-13T18:52:08.085+0000] {standard_task_runner.py:91} INFO - Job 179: Subtask dbt_run
[2024-11-13T18:52:08.087+0000] {logging_mixin.py:188} WARNING - /home/***/.local/lib/python3.12/site-packages/***/task/task_runner/standard_task_runner.py:61 DeprecationWarning: This process (pid=1433) is multi-threaded, use of fork() may lead to deadlocks in the child.
[2024-11-13T18:52:08.088+0000] {standard_task_runner.py:63} INFO - Started process 1434 to run task
[2024-11-13T18:52:08.150+0000] {task_command.py:426} INFO - Running <TaskInstance: BuildELT_dbt.dbt_run manual__2024-11-13T18:52:06.899530+00:00 [running]> on host d7a7afbedfaf
[2024-11-13T18:52:08.366+0000] {taskinstance.py:2648} INFO - Exporting env vars: AIRFLOW_CTX_DAG_OWNER='***' AIRFLOW_CTX_DAG_ID='BuildELT_dbt' AIRFLOW_CTX_TASK_ID='dbt_run' AIRFLOW_CTX_EXECUTION_DATE='2024-11-13T18:52:06.899530+00:00' AIRFLOW_CTX_TRY_NUMBER='1' AIRFLOW_CTX_DAG_RUN_ID='manual__2024-11-13T18:52:06.899530+00:00'
[2024-11-13T18:52:08.369+0000] {taskinstance.py:430} INFO - ::endgroup::
[2024-11-13T18:52:08.415+0000] {subprocess.py:63} INFO - Tmp dir root location: /tmp
[2024-11-13T18:52:08.418+0000] {subprocess.py:75} INFO - Running command: ['/usr/bin/bash', '-c', '/home/***/.local/bin/dbt run --profiles-dir /opt/***/dbt --project-dir /opt/***/dbt']
[2024-11-13T18:52:08.444+0000] {subprocess.py:86} INFO - Output:
[2024-11-13T18:52:10.864+0000] {subprocess.py:93} INFO - [0m18:52:10  Running with dbt=1.8.7
[2024-11-13T18:52:12.954+0000] {subprocess.py:93} INFO - [0m18:52:12  Registered adapter: snowflake=1.8.4
[2024-11-13T18:52:14.047+0000] {subprocess.py:93} INFO - [0m18:52:14  Found 6 models, 1 snapshot, 2 data tests, 2 sources, 459 macros
[2024-11-13T18:52:14.051+0000] {subprocess.py:93} INFO - [0m18:52:14
[2024-11-13T18:52:16.601+0000] {subprocess.py:93} INFO - [0m18:52:16  Concurrency: 1 threads (target='dev')
[2024-11-13T18:52:16.601+0000] {subprocess.py:93} INFO - [0m18:52:16
[2024-11-13T18:52:16.703+0000] {subprocess.py:93} INFO - [0m18:52:16  1 of 1 START sql table model analytics.stock_indicators ........................ [RUN]
[2024-11-13T18:52:17.501+0000] {subprocess.py:93} INFO - [0m18:52:17  1 of 1 ERROR creating sql table model analytics.stock_indicators ............... [[31mERROR[0m in 0.79s]
[2024-11-13T18:52:17.505+0000] {subprocess.py:93} INFO - [0m18:52:17
[2024-11-13T18:52:17.506+0000] {subprocess.py:93} INFO - [0m18:52:17  Finished running 1 table model in 0 hours 0 minutes and 3.45 seconds (3.45s).
[2024-11-13T18:52:17.558+0000] {subprocess.py:93} INFO - [0m18:52:17
[2024-11-13T18:52:17.559+0000] {subprocess.py:93} INFO - [0m18:52:17  [31mCompleted with 1 error and 0 warnings:[0m
[2024-11-13T18:52:17.560+0000] {subprocess.py:93} INFO - [0m18:52:17
[2024-11-13T18:52:17.562+0000] {subprocess.py:93} INFO - [0m18:52:17    Database Error in model stock_indicators (models/output/stock_indicators.sql)
[2024-11-13T18:52:17.562+0000] {subprocess.py:93} INFO -   001003 (42000): SQL compilation error:
[2024-11-13T18:52:17.563+0000] {subprocess.py:93} INFO -   syntax error line 118 at position 8 unexpected ';'.
[2024-11-13T18:52:17.564+0000] {subprocess.py:93} INFO -   compiled code at target/run/lab2/models/output/stock_indicators.sql
[2024-11-13T18:52:17.564+0000] {subprocess.py:93} INFO - [0m18:52:17
[2024-11-13T18:52:17.564+0000] {subprocess.py:93} INFO - [0m18:52:17  Done. PASS=0 WARN=0 ERROR=1 SKIP=0 TOTAL=1
[2024-11-13T18:52:18.426+0000] {subprocess.py:97} INFO - Command exited with return code 1
[2024-11-13T18:52:18.428+0000] {taskinstance.py:441} INFO - ::group::Post task execution logs
[2024-11-13T18:52:18.438+0000] {taskinstance.py:2905} ERROR - Task failed with exception
Traceback (most recent call last):
  File "/home/airflow/.local/lib/python3.12/site-packages/airflow/models/taskinstance.py", line 465, in _execute_task
    result = _execute_callable(context=context, **execute_callable_kwargs)
             ^^^^^^^^^^^^^^^^^^^^^^^^^^^^^^^^^^^^^^^^^^^^^^^^^^^^^^^^^^^^^
  File "/home/airflow/.local/lib/python3.12/site-packages/airflow/models/taskinstance.py", line 432, in _execute_callable
    return execute_callable(context=context, **execute_callable_kwargs)
           ^^^^^^^^^^^^^^^^^^^^^^^^^^^^^^^^^^^^^^^^^^^^^^^^^^^^^^^^^^^^
  File "/home/airflow/.local/lib/python3.12/site-packages/airflow/models/baseoperator.py", line 400, in wrapper
    return func(self, *args, **kwargs)
           ^^^^^^^^^^^^^^^^^^^^^^^^^^^
  File "/home/airflow/.local/lib/python3.12/site-packages/airflow/operators/bash.py", line 243, in execute
    raise AirflowException(
airflow.exceptions.AirflowException: Bash command failed. The command returned a non-zero exit code 1.
[2024-11-13T18:52:18.442+0000] {taskinstance.py:1206} INFO - Marking task as FAILED. dag_id=BuildELT_dbt, task_id=dbt_run, run_id=manual__2024-11-13T18:52:06.899530+00:00, execution_date=20241113T185206, start_date=20241113T185208, end_date=20241113T185218
[2024-11-13T18:52:18.457+0000] {standard_task_runner.py:110} ERROR - Failed to execute job 179 for task dbt_run (Bash command failed. The command returned a non-zero exit code 1.; 1434)
[2024-11-13T18:52:18.471+0000] {local_task_job_runner.py:240} INFO - Task exited with return code 1
[2024-11-13T18:52:18.495+0000] {taskinstance.py:3498} INFO - 0 downstream tasks scheduled from follow-on schedule check
[2024-11-13T18:52:18.500+0000] {local_task_job_runner.py:222} INFO - ::endgroup::
