[2024-11-30T08:26:47.484+0000] {local_task_job_runner.py:120} INFO - ::group::Pre task execution logs
[2024-11-30T08:26:47.645+0000] {taskinstance.py:2076} INFO - Dependencies all met for dep_context=non-requeueable deps ti=<TaskInstance: dbt-viz-dag.dbt_run manual__2024-11-30T08:26:43.567252+00:00 [queued]>
[2024-11-30T08:26:47.667+0000] {taskinstance.py:2076} INFO - Dependencies all met for dep_context=requeueable deps ti=<TaskInstance: dbt-viz-dag.dbt_run manual__2024-11-30T08:26:43.567252+00:00 [queued]>
[2024-11-30T08:26:47.669+0000] {taskinstance.py:2306} INFO - Starting attempt 1 of 1
[2024-11-30T08:26:47.706+0000] {taskinstance.py:2330} INFO - Executing <Task(BashOperator): dbt_run> on 2024-11-30 08:26:43.567252+00:00
[2024-11-30T08:26:47.723+0000] {standard_task_runner.py:90} INFO - Running: ['***', 'tasks', 'run', 'dbt-viz-dag', 'dbt_run', 'manual__2024-11-30T08:26:43.567252+00:00', '--job-id', '406', '--raw', '--subdir', 'DAGS_FOLDER/dbt-viz-dag.py', '--cfg-path', '/tmp/tmpj46qbti8']
[2024-11-30T08:26:47.727+0000] {standard_task_runner.py:91} INFO - Job 406: Subtask dbt_run
[2024-11-30T08:26:47.729+0000] {logging_mixin.py:188} WARNING - /home/***/.local/lib/python3.12/site-packages/***/task/task_runner/standard_task_runner.py:61 DeprecationWarning: This process (pid=1481) is multi-threaded, use of fork() may lead to deadlocks in the child.
[2024-11-30T08:26:47.731+0000] {standard_task_runner.py:63} INFO - Started process 1484 to run task
[2024-11-30T08:26:47.805+0000] {task_command.py:426} INFO - Running <TaskInstance: dbt-viz-dag.dbt_run manual__2024-11-30T08:26:43.567252+00:00 [running]> on host e060654747dc
[2024-11-30T08:26:48.117+0000] {taskinstance.py:2648} INFO - Exporting env vars: AIRFLOW_CTX_DAG_OWNER='***' AIRFLOW_CTX_DAG_ID='dbt-viz-dag' AIRFLOW_CTX_TASK_ID='dbt_run' AIRFLOW_CTX_EXECUTION_DATE='2024-11-30T08:26:43.567252+00:00' AIRFLOW_CTX_TRY_NUMBER='1' AIRFLOW_CTX_DAG_RUN_ID='manual__2024-11-30T08:26:43.567252+00:00'
[2024-11-30T08:26:48.118+0000] {taskinstance.py:430} INFO - ::endgroup::
[2024-11-30T08:26:48.181+0000] {subprocess.py:63} INFO - Tmp dir root location: /tmp
[2024-11-30T08:26:48.191+0000] {subprocess.py:75} INFO - Running command: ['/usr/bin/bash', '-c', '/home/***/.local/bin/dbt run --profiles-dir /opt/***/dbt_viz --project-dir /opt/***/dbt_viz']
[2024-11-30T08:26:48.209+0000] {subprocess.py:86} INFO - Output:
[2024-11-30T08:26:53.194+0000] {subprocess.py:93} INFO - [0m08:26:53  Running with dbt=1.8.7
[2024-11-30T08:26:57.289+0000] {subprocess.py:93} INFO - [0m08:26:57  Registered adapter: snowflake=1.8.4
[2024-11-30T08:26:58.666+0000] {subprocess.py:93} INFO - [0m08:26:58  Found 4 models, 1 test, 3 sources, 459 macros
[2024-11-30T08:26:58.671+0000] {subprocess.py:93} INFO - [0m08:26:58
[2024-11-30T08:27:00.835+0000] {subprocess.py:93} INFO - [0m08:27:00  Concurrency: 1 threads (target='dev')
[2024-11-30T08:27:00.838+0000] {subprocess.py:93} INFO - [0m08:27:00
[2024-11-30T08:27:00.988+0000] {subprocess.py:93} INFO - [0m08:27:00  1 of 2 START sql table model analytics.energy_demand_final_data ................ [RUN]
[2024-11-30T08:27:02.359+0000] {subprocess.py:93} INFO - [0m08:27:02  1 of 2 ERROR creating sql table model analytics.energy_demand_final_data ....... [[31mERROR[0m in 1.36s]
[2024-11-30T08:27:02.368+0000] {subprocess.py:93} INFO - [0m08:27:02  2 of 2 START sql table model analytics.energy_historical_forecast_data ......... [RUN]
[2024-11-30T08:27:04.822+0000] {subprocess.py:93} INFO - [0m08:27:04  2 of 2 OK created sql table model analytics.energy_historical_forecast_data .... [[32mSUCCESS 1[0m in 2.45s]
[2024-11-30T08:27:04.834+0000] {subprocess.py:93} INFO - [0m08:27:04
[2024-11-30T08:27:04.835+0000] {subprocess.py:93} INFO - [0m08:27:04  Finished running 2 table models in 0 hours 0 minutes and 6.16 seconds (6.16s).
[2024-11-30T08:27:04.958+0000] {subprocess.py:93} INFO - [0m08:27:04
[2024-11-30T08:27:04.960+0000] {subprocess.py:93} INFO - [0m08:27:04  [31mCompleted with 1 error and 0 warnings:[0m
[2024-11-30T08:27:04.963+0000] {subprocess.py:93} INFO - [0m08:27:04
[2024-11-30T08:27:04.966+0000] {subprocess.py:93} INFO - [0m08:27:04    Database Error in model energy_demand_final_data (models/output/energy_demand_final_data.sql)
[2024-11-30T08:27:04.967+0000] {subprocess.py:93} INFO -   002003 (42S02): SQL compilation error:
[2024-11-30T08:27:04.968+0000] {subprocess.py:93} INFO -   Object 'REFENERGY_HISTORICAL_FORECAST_DATA' does not exist or not authorized.
[2024-11-30T08:27:04.969+0000] {subprocess.py:93} INFO -   compiled code at target/run/project/models/output/energy_demand_final_data.sql
[2024-11-30T08:27:04.970+0000] {subprocess.py:93} INFO - [0m08:27:04
[2024-11-30T08:27:04.971+0000] {subprocess.py:93} INFO - [0m08:27:04  Done. PASS=1 WARN=0 ERROR=1 SKIP=0 TOTAL=2
[2024-11-30T08:27:06.075+0000] {subprocess.py:97} INFO - Command exited with return code 1
[2024-11-30T08:27:06.081+0000] {taskinstance.py:441} INFO - ::group::Post task execution logs
[2024-11-30T08:27:06.118+0000] {taskinstance.py:2905} ERROR - Task failed with exception
Traceback (most recent call last):
  File "/home/airflow/.local/lib/python3.12/site-packages/airflow/models/taskinstance.py", line 465, in _execute_task
    result = _execute_callable(context=context, **execute_callable_kwargs)
             ^^^^^^^^^^^^^^^^^^^^^^^^^^^^^^^^^^^^^^^^^^^^^^^^^^^^^^^^^^^^^
  File "/home/airflow/.local/lib/python3.12/site-packages/airflow/models/taskinstance.py", line 432, in _execute_callable
    return execute_callable(context=context, **execute_callable_kwargs)
           ^^^^^^^^^^^^^^^^^^^^^^^^^^^^^^^^^^^^^^^^^^^^^^^^^^^^^^^^^^^^
  File "/home/airflow/.local/lib/python3.12/site-packages/airflow/models/baseoperator.py", line 400, in wrapper
    return func(self, *args, **kwargs)
           ^^^^^^^^^^^^^^^^^^^^^^^^^^^
  File "/home/airflow/.local/lib/python3.12/site-packages/airflow/operators/bash.py", line 243, in execute
    raise AirflowException(
airflow.exceptions.AirflowException: Bash command failed. The command returned a non-zero exit code 1.
[2024-11-30T08:27:06.154+0000] {taskinstance.py:1206} INFO - Marking task as FAILED. dag_id=dbt-viz-dag, task_id=dbt_run, run_id=manual__2024-11-30T08:26:43.567252+00:00, execution_date=20241130T082643, start_date=20241130T082647, end_date=20241130T082706
[2024-11-30T08:27:06.199+0000] {standard_task_runner.py:110} ERROR - Failed to execute job 406 for task dbt_run (Bash command failed. The command returned a non-zero exit code 1.; 1484)
[2024-11-30T08:27:06.234+0000] {local_task_job_runner.py:240} INFO - Task exited with return code 1
[2024-11-30T08:27:06.281+0000] {taskinstance.py:3498} INFO - 0 downstream tasks scheduled from follow-on schedule check
[2024-11-30T08:27:06.295+0000] {local_task_job_runner.py:222} INFO - ::endgroup::
