[2024-12-05T07:29:15.502+0000] {local_task_job_runner.py:120} INFO - ::group::Pre task execution logs
[2024-12-05T07:29:15.544+0000] {taskinstance.py:2076} INFO - Dependencies all met for dep_context=non-requeueable deps ti=<TaskInstance: complete-dag.dbt_snapshot_2 manual__2024-12-05T07:22:06.354169+00:00 [queued]>
[2024-12-05T07:29:15.556+0000] {taskinstance.py:2076} INFO - Dependencies all met for dep_context=requeueable deps ti=<TaskInstance: complete-dag.dbt_snapshot_2 manual__2024-12-05T07:22:06.354169+00:00 [queued]>
[2024-12-05T07:29:15.557+0000] {taskinstance.py:2306} INFO - Starting attempt 1 of 1
[2024-12-05T07:29:15.575+0000] {taskinstance.py:2330} INFO - Executing <Task(BashOperator): dbt_snapshot_2> on 2024-12-05 07:22:06.354169+00:00
[2024-12-05T07:29:15.588+0000] {logging_mixin.py:188} WARNING - /home/***/.local/lib/python3.12/site-packages/***/task/task_runner/standard_task_runner.py:61 DeprecationWarning: This process (pid=1155) is multi-threaded, use of fork() may lead to deadlocks in the child.
[2024-12-05T07:29:15.590+0000] {standard_task_runner.py:63} INFO - Started process 1158 to run task
[2024-12-05T07:29:15.589+0000] {standard_task_runner.py:90} INFO - Running: ['***', 'tasks', 'run', 'complete-dag', 'dbt_snapshot_2', 'manual__2024-12-05T07:22:06.354169+00:00', '--job-id', '515', '--raw', '--subdir', 'DAGS_FOLDER/complete_dag.py', '--cfg-path', '/tmp/tmpoq5wc1cl']
[2024-12-05T07:29:15.591+0000] {standard_task_runner.py:91} INFO - Job 515: Subtask dbt_snapshot_2
[2024-12-05T07:29:15.653+0000] {task_command.py:426} INFO - Running <TaskInstance: complete-dag.dbt_snapshot_2 manual__2024-12-05T07:22:06.354169+00:00 [running]> on host e060654747dc
[2024-12-05T07:29:15.867+0000] {taskinstance.py:2648} INFO - Exporting env vars: AIRFLOW_CTX_DAG_OWNER='***' AIRFLOW_CTX_DAG_ID='complete-dag' AIRFLOW_CTX_TASK_ID='dbt_snapshot_2' AIRFLOW_CTX_EXECUTION_DATE='2024-12-05T07:22:06.354169+00:00' AIRFLOW_CTX_TRY_NUMBER='1' AIRFLOW_CTX_DAG_RUN_ID='manual__2024-12-05T07:22:06.354169+00:00'
[2024-12-05T07:29:15.868+0000] {taskinstance.py:430} INFO - ::endgroup::
[2024-12-05T07:29:15.870+0000] {subprocess.py:63} INFO - Tmp dir root location: /tmp
[2024-12-05T07:29:15.872+0000] {subprocess.py:75} INFO - Running command: ['/usr/bin/bash', '-c', '/home/***/.local/bin/dbt snapshot --profiles-dir /opt/***/dbt_viz --project-dir /opt/***/dbt_viz']
[2024-12-05T07:29:15.893+0000] {subprocess.py:86} INFO - Output:
[2024-12-05T07:29:19.216+0000] {subprocess.py:93} INFO - [0m07:29:19  Running with dbt=1.8.7
[2024-12-05T07:29:20.585+0000] {subprocess.py:93} INFO - [0m07:29:20  Registered adapter: snowflake=1.8.4
[2024-12-05T07:29:21.536+0000] {subprocess.py:93} INFO - [0m07:29:21  Found 4 models, 1 test, 1 snapshot, 3 sources, 459 macros
[2024-12-05T07:29:21.540+0000] {subprocess.py:93} INFO - [0m07:29:21
[2024-12-05T07:29:24.445+0000] {subprocess.py:93} INFO - [0m07:29:24  Concurrency: 1 threads (target='dev')
[2024-12-05T07:29:24.449+0000] {subprocess.py:93} INFO - [0m07:29:24
[2024-12-05T07:29:24.469+0000] {subprocess.py:93} INFO - [0m07:29:24  1 of 1 START snapshot snapshot.energy_demand_final_snapshot .................... [RUN]
[2024-12-05T07:29:25.228+0000] {subprocess.py:93} INFO - [0m07:29:25  1 of 1 ERROR snapshotting snapshot.energy_demand_final_snapshot ................ [[31mERROR[0m in 0.75s]
[2024-12-05T07:29:25.237+0000] {subprocess.py:93} INFO - [0m07:29:25
[2024-12-05T07:29:25.238+0000] {subprocess.py:93} INFO - [0m07:29:25  Finished running 1 snapshot in 0 hours 0 minutes and 3.70 seconds (3.70s).
[2024-12-05T07:29:25.329+0000] {subprocess.py:93} INFO - [0m07:29:25
[2024-12-05T07:29:25.332+0000] {subprocess.py:93} INFO - [0m07:29:25  [31mCompleted with 1 error and 0 warnings:[0m
[2024-12-05T07:29:25.334+0000] {subprocess.py:93} INFO - [0m07:29:25
[2024-12-05T07:29:25.335+0000] {subprocess.py:93} INFO - [0m07:29:25    Database Error in snapshot energy_demand_final_snapshot (snapshots/energy_demand_final_snapshot.sql)
[2024-12-05T07:29:25.336+0000] {subprocess.py:93} INFO -   000904 (42000): SQL compilation error: error line 6 at position 26
[2024-12-05T07:29:25.336+0000] {subprocess.py:93} INFO -   invalid identifier 'UNIQUE_ID'
[2024-12-05T07:29:25.337+0000] {subprocess.py:93} INFO - [0m07:29:25
[2024-12-05T07:29:25.338+0000] {subprocess.py:93} INFO - [0m07:29:25  Done. PASS=0 WARN=0 ERROR=1 SKIP=0 TOTAL=1
[2024-12-05T07:29:26.333+0000] {subprocess.py:97} INFO - Command exited with return code 1
[2024-12-05T07:29:26.334+0000] {taskinstance.py:441} INFO - ::group::Post task execution logs
[2024-12-05T07:29:26.347+0000] {taskinstance.py:2905} ERROR - Task failed with exception
Traceback (most recent call last):
  File "/home/airflow/.local/lib/python3.12/site-packages/airflow/models/taskinstance.py", line 465, in _execute_task
    result = _execute_callable(context=context, **execute_callable_kwargs)
             ^^^^^^^^^^^^^^^^^^^^^^^^^^^^^^^^^^^^^^^^^^^^^^^^^^^^^^^^^^^^^
  File "/home/airflow/.local/lib/python3.12/site-packages/airflow/models/taskinstance.py", line 432, in _execute_callable
    return execute_callable(context=context, **execute_callable_kwargs)
           ^^^^^^^^^^^^^^^^^^^^^^^^^^^^^^^^^^^^^^^^^^^^^^^^^^^^^^^^^^^^
  File "/home/airflow/.local/lib/python3.12/site-packages/airflow/models/baseoperator.py", line 400, in wrapper
    return func(self, *args, **kwargs)
           ^^^^^^^^^^^^^^^^^^^^^^^^^^^
  File "/home/airflow/.local/lib/python3.12/site-packages/airflow/operators/bash.py", line 243, in execute
    raise AirflowException(
airflow.exceptions.AirflowException: Bash command failed. The command returned a non-zero exit code 1.
[2024-12-05T07:29:26.355+0000] {taskinstance.py:1206} INFO - Marking task as FAILED. dag_id=complete-dag, task_id=dbt_snapshot_2, run_id=manual__2024-12-05T07:22:06.354169+00:00, execution_date=20241205T072206, start_date=20241205T072915, end_date=20241205T072926
[2024-12-05T07:29:26.378+0000] {standard_task_runner.py:110} ERROR - Failed to execute job 515 for task dbt_snapshot_2 (Bash command failed. The command returned a non-zero exit code 1.; 1158)
[2024-12-05T07:29:26.410+0000] {local_task_job_runner.py:240} INFO - Task exited with return code 1
[2024-12-05T07:29:26.431+0000] {taskinstance.py:3498} INFO - 0 downstream tasks scheduled from follow-on schedule check
[2024-12-05T07:29:26.435+0000] {local_task_job_runner.py:222} INFO - ::endgroup::
