[2024-11-28T20:53:31.865+0000] {local_task_job_runner.py:120} INFO - ::group::Pre task execution logs
[2024-11-28T20:53:31.941+0000] {taskinstance.py:2076} INFO - Dependencies all met for dep_context=non-requeueable deps ti=<TaskInstance: dbt-dag.dbt_test manual__2024-11-28T20:53:16.030280+00:00 [queued]>
[2024-11-28T20:53:31.951+0000] {taskinstance.py:2076} INFO - Dependencies all met for dep_context=requeueable deps ti=<TaskInstance: dbt-dag.dbt_test manual__2024-11-28T20:53:16.030280+00:00 [queued]>
[2024-11-28T20:53:31.952+0000] {taskinstance.py:2306} INFO - Starting attempt 1 of 1
[2024-11-28T20:53:31.971+0000] {taskinstance.py:2330} INFO - Executing <Task(BashOperator): dbt_test> on 2024-11-28 20:53:16.030280+00:00
[2024-11-28T20:53:31.980+0000] {standard_task_runner.py:90} INFO - Running: ['***', 'tasks', 'run', 'dbt-dag', 'dbt_test', 'manual__2024-11-28T20:53:16.030280+00:00', '--job-id', '250', '--raw', '--subdir', 'DAGS_FOLDER/dbt-dag.py', '--cfg-path', '/tmp/tmpz12fj9p9']
[2024-11-28T20:53:31.982+0000] {standard_task_runner.py:91} INFO - Job 250: Subtask dbt_test
[2024-11-28T20:53:31.984+0000] {logging_mixin.py:188} WARNING - /home/***/.local/lib/python3.12/site-packages/***/task/task_runner/standard_task_runner.py:61 DeprecationWarning: This process (pid=2435) is multi-threaded, use of fork() may lead to deadlocks in the child.
[2024-11-28T20:53:31.985+0000] {standard_task_runner.py:63} INFO - Started process 2436 to run task
[2024-11-28T20:53:32.035+0000] {task_command.py:426} INFO - Running <TaskInstance: dbt-dag.dbt_test manual__2024-11-28T20:53:16.030280+00:00 [running]> on host fd43cd87157f
[2024-11-28T20:53:32.205+0000] {taskinstance.py:2648} INFO - Exporting env vars: AIRFLOW_CTX_DAG_OWNER='***' AIRFLOW_CTX_DAG_ID='dbt-dag' AIRFLOW_CTX_TASK_ID='dbt_test' AIRFLOW_CTX_EXECUTION_DATE='2024-11-28T20:53:16.030280+00:00' AIRFLOW_CTX_TRY_NUMBER='1' AIRFLOW_CTX_DAG_RUN_ID='manual__2024-11-28T20:53:16.030280+00:00'
[2024-11-28T20:53:32.206+0000] {taskinstance.py:430} INFO - ::endgroup::
[2024-11-28T20:53:32.244+0000] {subprocess.py:63} INFO - Tmp dir root location: /tmp
[2024-11-28T20:53:32.247+0000] {subprocess.py:75} INFO - Running command: ['/usr/bin/bash', '-c', '/home/***/.local/bin/dbt test --profiles-dir /opt/***/dbt --project-dir /opt/***/dbt']
[2024-11-28T20:53:32.262+0000] {subprocess.py:86} INFO - Output:
[2024-11-28T20:53:34.770+0000] {subprocess.py:93} INFO - [0m20:53:34  Running with dbt=1.8.7
[2024-11-28T20:53:36.044+0000] {subprocess.py:93} INFO - [0m20:53:36  Registered adapter: snowflake=1.8.4
[2024-11-28T20:53:36.817+0000] {subprocess.py:93} INFO - [0m20:53:36  Found 4 models, 3 data tests, 3 sources, 459 macros
[2024-11-28T20:53:36.822+0000] {subprocess.py:93} INFO - [0m20:53:36
[2024-11-28T20:53:37.927+0000] {subprocess.py:93} INFO - [0m20:53:37  Concurrency: 1 threads (target='dev')
[2024-11-28T20:53:37.928+0000] {subprocess.py:93} INFO - [0m20:53:37
[2024-11-28T20:53:37.939+0000] {subprocess.py:93} INFO - [0m20:53:37  1 of 3 START test not_null_electricity_weather_viz_ready_energy_per_degree_temp  [RUN]
[2024-11-28T20:53:39.057+0000] {subprocess.py:93} INFO - [0m20:53:39  1 of 3 FAIL 4 not_null_electricity_weather_viz_ready_energy_per_degree_temp .... [[31mFAIL 4[0m in 1.12s]
[2024-11-28T20:53:39.061+0000] {subprocess.py:93} INFO - [0m20:53:39  2 of 3 START test not_null_electricity_weather_viz_ready_subba_energy_mwh ...... [RUN]
[2024-11-28T20:53:40.002+0000] {subprocess.py:93} INFO - [0m20:53:40  2 of 3 PASS not_null_electricity_weather_viz_ready_subba_energy_mwh ............ [[32mPASS[0m in 0.94s]
[2024-11-28T20:53:40.005+0000] {subprocess.py:93} INFO - [0m20:53:40  3 of 3 START test not_null_electricity_weather_viz_ready_total_daily_energy_mwh  [RUN]
[2024-11-28T20:53:40.982+0000] {subprocess.py:93} INFO - [0m20:53:40  3 of 3 PASS not_null_electricity_weather_viz_ready_total_daily_energy_mwh ...... [[32mPASS[0m in 0.98s]
[2024-11-28T20:53:40.988+0000] {subprocess.py:93} INFO - [0m20:53:40
[2024-11-28T20:53:40.989+0000] {subprocess.py:93} INFO - [0m20:53:40  Finished running 3 data tests in 0 hours 0 minutes and 4.16 seconds (4.16s).
[2024-11-28T20:53:41.067+0000] {subprocess.py:93} INFO - [0m20:53:41
[2024-11-28T20:53:41.068+0000] {subprocess.py:93} INFO - [0m20:53:41  [31mCompleted with 1 error and 0 warnings:[0m
[2024-11-28T20:53:41.070+0000] {subprocess.py:93} INFO - [0m20:53:41
[2024-11-28T20:53:41.071+0000] {subprocess.py:93} INFO - [0m20:53:41  [31mFailure in test not_null_electricity_weather_viz_ready_energy_per_degree_temp (models/schema.yml)[0m
[2024-11-28T20:53:41.072+0000] {subprocess.py:93} INFO - [0m20:53:41    Got 4 results, configured to fail if != 0
[2024-11-28T20:53:41.074+0000] {subprocess.py:93} INFO - [0m20:53:41
[2024-11-28T20:53:41.075+0000] {subprocess.py:93} INFO - [0m20:53:41    compiled code at target/compiled/lab2/models/schema.yml/not_null_electricity_weather_viz_ready_energy_per_degree_temp.sql
[2024-11-28T20:53:41.076+0000] {subprocess.py:93} INFO - [0m20:53:41
[2024-11-28T20:53:41.078+0000] {subprocess.py:93} INFO - [0m20:53:41  Done. PASS=2 WARN=0 ERROR=1 SKIP=0 TOTAL=3
[2024-11-28T20:53:41.914+0000] {subprocess.py:97} INFO - Command exited with return code 1
[2024-11-28T20:53:41.915+0000] {taskinstance.py:441} INFO - ::group::Post task execution logs
[2024-11-28T20:53:41.927+0000] {taskinstance.py:2905} ERROR - Task failed with exception
Traceback (most recent call last):
  File "/home/airflow/.local/lib/python3.12/site-packages/airflow/models/taskinstance.py", line 465, in _execute_task
    result = _execute_callable(context=context, **execute_callable_kwargs)
             ^^^^^^^^^^^^^^^^^^^^^^^^^^^^^^^^^^^^^^^^^^^^^^^^^^^^^^^^^^^^^
  File "/home/airflow/.local/lib/python3.12/site-packages/airflow/models/taskinstance.py", line 432, in _execute_callable
    return execute_callable(context=context, **execute_callable_kwargs)
           ^^^^^^^^^^^^^^^^^^^^^^^^^^^^^^^^^^^^^^^^^^^^^^^^^^^^^^^^^^^^
  File "/home/airflow/.local/lib/python3.12/site-packages/airflow/models/baseoperator.py", line 400, in wrapper
    return func(self, *args, **kwargs)
           ^^^^^^^^^^^^^^^^^^^^^^^^^^^
  File "/home/airflow/.local/lib/python3.12/site-packages/airflow/operators/bash.py", line 243, in execute
    raise AirflowException(
airflow.exceptions.AirflowException: Bash command failed. The command returned a non-zero exit code 1.
[2024-11-28T20:53:41.933+0000] {taskinstance.py:1206} INFO - Marking task as FAILED. dag_id=dbt-dag, task_id=dbt_test, run_id=manual__2024-11-28T20:53:16.030280+00:00, execution_date=20241128T205316, start_date=20241128T205331, end_date=20241128T205341
[2024-11-28T20:53:41.949+0000] {standard_task_runner.py:110} ERROR - Failed to execute job 250 for task dbt_test (Bash command failed. The command returned a non-zero exit code 1.; 2436)
[2024-11-28T20:53:41.998+0000] {local_task_job_runner.py:240} INFO - Task exited with return code 1
[2024-11-28T20:53:42.032+0000] {taskinstance.py:3498} INFO - 0 downstream tasks scheduled from follow-on schedule check
[2024-11-28T20:53:42.042+0000] {local_task_job_runner.py:222} INFO - ::endgroup::
